Workbook
Name AirRet: Returns!$C$6:INDEX(Returns!$C$6:$C$1000,COUNT(Returns!$A$6:$A$1000))
Name BenchRet: Returns!$I$6:INDEX(Returns!$I$6:$I$1000,COUNT(Returns!$A$6:$A$1000))
Name CipRet: Returns!$F$6:INDEX(Returns!$F$6:$F$1000,COUNT(Returns!$A$6:$A$1000))
Name CompanyNames: Holdings!$C$7:$C$13
Name CurrentPortValue: Drawdown!$X$1005
Name DD_BenchDD: Drawdown!$I$9:INDEX(Drawdown!$I$7:$I$1000,COUNT(Drawdown!$A$7:$A$1000))
Name DD_BenchVal: Drawdown!$G$9:INDEX(Drawdown!$G$7:$G$1000,COUNT(Drawdown!$A$7:$A$1000))
Name DD_ChartBenchDD: Drawdown!$R$7:INDEX(Drawdown!$R$7:$R$1000,COUNT(Drawdown!$A$7:$A$1000))
Name DD_ChartBenchVal: Drawdown!$N$7:INDEX(Drawdown!$N$7:$N$1000,COUNT(Drawdown!$A$7:$A$1000))
Name DD_ChartDates: Drawdown!$L$7:INDEX(Drawdown!$L$7:$L$1000,COUNT(Drawdown!$A$7:$A$1000))
Name DD_ChartDDDates: Drawdown!$P$7:INDEX(Drawdown!$P$7:$P$1000,COUNT(Drawdown!$A$7:$A$1000))
Name DD_ChartPortDD: Drawdown!$Q$7:INDEX(Drawdown!$Q$7:$Q$1000,COUNT(Drawdown!$A$7:$A$1000))
Name DD_ChartPortVal: Drawdown!$M$7:INDEX(Drawdown!$M$7:$M$1000,COUNT(Drawdown!$A$7:$A$1000))
Name DD_Dates: Drawdown!$J$9:INDEX(Drawdown!$J$7:$J$1000,COUNT(Drawdown!$A$7:$A$1000))
Name DD_PortDD: Drawdown!$E$9:INDEX(Drawdown!$E$7:$E$1000,COUNT(Drawdown!$A$7:$A$1000))
Name DD_PortVal: Drawdown!$C$9:INDEX(Drawdown!$C$7:$C$1000,COUNT(Drawdown!$A$7:$A$1000))
Name HclRet: Returns!$H$6:INDEX(Returns!$H$6:$H$1000,COUNT(Returns!$A$6:$A$1000))
Name HdfRet: Returns!$D$6:INDEX(Returns!$D$6:$D$1000,COUNT(Returns!$A$6:$A$1000))
Name IndexBase: Inputs!$B$12
Name LatestObsDate: Drawdown!$X$1009
Name LtRet: Returns!$E$6:INDEX(Returns!$E$6:$E$1000,COUNT(Returns!$A$6:$A$1000))
Name MarRet: Returns!$G$6:INDEX(Returns!$G$6:$G$1000,COUNT(Returns!$A$6:$A$1000))
Name NotionalValue: Inputs!$B$13
Name PortfolioPnL: Drawdown!$X$1006
Name PortRet: Returns!$J$6:INDEX(Returns!$J$6:$J$1000,COUNT(Returns!$A$6:$A$1000))
Name PortValueDates: Drawdown!$T$7:INDEX(Drawdown!$T$7:$T$1000,COUNT(Drawdown!$A$7:$A$1000))
Name PortValueSeries: Drawdown!$U$7:INDEX(Drawdown!$U$7:$U$1000,COUNT(Drawdown!$A$7:$A$1000))
Name RelRet: Returns!$B$6:INDEX(Returns!$B$6:$B$1000,COUNT(Returns!$A$6:$A$1000))
Name RiskFree: Inputs!$B$18
Name StockRets: Returns!$B$6:INDEX(Returns!$B$6:$H$1000,COUNT(Returns!$A$6:$A$1000),7)
Name Thr30: Inputs!$B$37
Name Thr50: Inputs!$B$36
Name Thr80: Inputs!$B$35
Name Tickers: Holdings!$B$7:$B$13
Name WeeksPerYear: Inputs!$B$11
Name Weights: Returns!$B$4:$H$4
Name WeightsCol: Holdings!$E$7:$E$13

Sheet Overview
A1: PERSONAL PORTFOLIO ANALYSIS
A2: Indian Equity Portfolio vs NIFTY 50 · 7 holdings · weekly data · Excel 365
A4: PORTFOLIO OBJECTIVE
A5: Objective | B5: Measure return, risk, risk-adjusted return, systematic risk (beta/alpha), diversification and drawdown for a seven-stock Indian equity book against the NIFTY 50 — from one weekly return series, with every figure a live formula.
A7: KEY FACTS
A8: Benchmark | B8: NIFTY 50 (^NSEI) — price index
A9: Analysis period | B9: ="Weekly, "&TEXT(Inputs!$B$6,"dd-mmm-yyyy")&" to "&TEXT(Inputs!$B$7,"dd-mmm-yyyy")&" ("&TEXT(Inputs!$B$9,"0")&" weekly returns, ≈2 years)" -> Weekly, 09-Sep-2024 to 07-Sep-2026 (104 weekly returns, ≈2 years)
A10: Data frequency | B10: Weekly (Monday week-start), adjusted close
A11: Risk-free rate | B11: =RiskFree -> 0.0695
A12: Holdings / sectors | B12: 7 holdings across 7 sectors, static target weights, no rebalancing drift
A14: PORTFOLIO HOLDINGS & WEIGHTS
A15: # | B15: Ticker | C15: Company | D15: Sector | E15: Weight
A16: 1 | B16: RELIANCE.NS | C16: Reliance Industries | D16: Energy / Conglomerate | E16: =Holdings!$E$7 -> 0.23
A17: 2 | B17: BHARTIARTL.NS | C17: Bharti Airtel | D17: Telecom | E17: =Holdings!$E$8 -> 0.15
A18: 3 | B18: HDFCBANK.NS | C18: HDFC Bank | D18: Banking | E18: =Holdings!$E$9 -> 0.15
A19: 4 | B19: LT.NS | C19: Larsen & Toubro | D19: Industrials / Infrastructure | E19: =Holdings!$E$10 -> 0.14
A20: 5 | B20: CIPLA.NS | C20: Cipla | D20: Pharmaceuticals | E20: =Holdings!$E$11 -> 0.12
A21: 6 | B21: MARUTI.NS | C21: Maruti Suzuki | D21: Automobile | E21: =Holdings!$E$12 -> 0.12
A22: 7 | B22: HCLTECH.NS | C22: HCL Technologies | D22: Information Technology | E22: =Holdings!$E$13 -> 0.09
C23: TOTAL — must equal 100% | E23: =SUM(WeightsCol) -> 1 | G23: =IF(ROUND(SUM(WeightsCol),6)=1,"✓ PASS","✗ FAIL") -> ✓ PASS
A25: METRICS CALCULATED
A26: Return & risk | B26: Weekly return, annualised return (×52), annualised volatility (×√52), cumulative return and growth of ₹100 — for the portfolio and NIFTY 50 alike.
A27: Risk-adjusted | B27: Sharpe, Sortino and Treynor ratios on a documented, editable risk-free rate; beta, R² and CAPM-based Jensen's alpha vs NIFTY 50.
A28: Diversification & drawdown | B28: 7×7 correlation matrix on returns, running-peak drawdown engine, and return / risk contribution by holding via covariance decomposition.
A30: WORKBOOK NAVIGATION
A31: Overview | B31: This page — objective, holdings, methodology snapshot and navigation
A32: Inputs | B32: Every assumption and lever: risk-free rate, annualisation factor, data provenance
A33: Holdings | B33: Holdings table, weight check, sector allocation, full model quality checks
A34: Prices | B34: Rolling ~2-year dynamic price lookup layer (STOCKHISTORY-fed via Market_Data) — no calculations, no hardcoded prices
A35: Returns | B35: Weekly return series per security, benchmark and weighted portfolio — 100% formulas
A36: Risk_Analysis | B36: Return, volatility, Sharpe, Sortino, beta, alpha, Treynor, capture, per-security stats
A37: Correlation | B37: 7×7 matrix, ranked pairwise ladder, diversification diagnostics
A38: Drawdown | B38: Growth of ₹100, running peak and drawdown for portfolio and index
A39: Benchmark | B39: Head-to-head comparison, the six key questions, analyst commentary
A40: Contribution | B40: Return and risk attribution by holding
A41: Dashboard | B41: One-page premium factsheet — KPIs, charts, heatmap, insights
A43: MODEL ASSUMPTIONS
A44: Construction & costs | B44: Static target weights, no rebalancing drift, no transaction costs, taxes or dividend tax. Simple (not log) weekly returns; arithmetic annualisation (×52 / ×√52) shown alongside compounded cumulative return.
A45: Risk-free & benchmark | B45: Risk-free rate is a single editable input (India 10Y G-Sec, documented on Inputs) held constant over the window. NIFTY 50 price index is used, not the TRI — see limitations. Benchmark source is Power Query (primary, once set up — Market_Data §3) with a documented emergency static fallback, never STOCKHISTORY (tested, confirmed not to resolve for this index).
A47: LIMITATIONS
...

Sheet Inputs
A1: INPUTS & ASSUMPTIONS
A2: All model levers live here. Blue = hardcoded input you may edit · black = formula · green = link to another sheet.
A4: 1 · ANALYSIS PARAMETERS
A5: Parameter | B5: Value | C5: Unit | D5: Source / Basis
A6: Analysis start date | B6: =Prices!$A$4 -> 45544 | C6: date | D6: First weekly observation in source dataset
A7: Analysis end date | B7: =INDEX(Prices!$A$4:$A$133,COUNT(Prices!$A$4:$A$133)) -> 46272 | C7: date | D7: Last COMPLETED weekly observation (in-progress week excluded)
A8: Price observations | B8: =COUNT(Prices!$A$4:$A$133) -> 105 | C8: count | D8: Weekly closes per security, identical dates across all series
A9: Return observations | B9: =COUNT(PortRet) -> 104 | C9: count | D9: = price observations − 1
A10: Data frequency | B10: Weekly (Monday week-start) | C10: text | D10: Weekly reduces noise vs daily while retaining ~104 observations
A11: Periods per year | B11: 52 | C11: weeks | D11: Annualisation factor. Return × 52; volatility × SQRT(52)
A12: Growth index base | B12: 100 | C12: ₹ | D12: Both portfolio and benchmark growth series start at exactly ₹100
A13: Initial notional portfolio value | B13: 1000000 | C13: ₹ | D13: Editable input. Drives Holdings initial allocation (₹) and the weekly Portfolio Value series — NOT an actual investment
A14: Rebalancing assumption | B14: None — static target weights | C14: text | D14: Weights held constant every week; no drift, no transaction costs
A16: 2 · RISK-FREE RATE (editable — all Sharpe / Treynor / alpha outputs update)
A17: Parameter | B17: Value | C17: Unit | D17: Source / Basis
A18: Risk-free rate (annual) | B18: 0.0695 | C18: % p.a. | D18: India 10-Year Government Bond benchmark yield
A19: Rate as at | B19: 46272 | C19: date | D19: Latest quote available at time of build
A20: Source | B20: Trading Economics — India Government Bond 10Y | C20: text | D20: https://tradingeconomics.com/india/government-bond-yield
A21: Note | B21: This is an editable assumption, not a calculated output. Replace the yield above with your own sourced rate and every risk-adjusted metric in the workbook recalculates.
A23: 3 · MARKET DATA SOURCE
A24: Parameter | B24: Value | C24: Unit | D24: Source / Basis
A25: Data provider | B25: Yahoo Finance (chart API v8) | C25: text | D25: Retrieved programmatically; raw dataset preserved in data/prices_backup.csv
A26: Retrieved on | B26: 46273 | C26: date | D26: Snapshot date — dataset is static, not live-linked
A27: Price basis | B27: Adjusted close | C27: text | D27: Adjusted for splits and dividends — required for correct return series
A28: Currency | B28: INR (₹) | C28: text | D28: All securities and the benchmark quote in INR
A29: Exchange | B29: NSE (National Stock Exchange of India) | C29: text | D29: Yahoo suffix .NS
A30: Benchmark | B30: NIFTY 50 (^NSEI) | C30: text | D30: Price index level; NIFTY 50 TRI not used — see limitations
A31: Date alignment | B31: Identical weekly dates across all 8 series | C31: text | D31: Intersection of week-start dates; no forward-filling applied
A33: 4 · CORRELATION INTERPRETATION BANDS
A34: Band | B34: Threshold | C34: Unit | D34: Interpretation
A35: Potentially poor diversification | B35: 0.8 | C35: ρ > | D35: Pair behaves close to a single bet — review for redundancy
A36: Moderate / high relationship | B36: 0.5 | C36: ρ > | D36: Meaningful shared risk driver
A37: Moderate relationship | B37: 0.3 | C37: ρ > | D37: Some shared exposure, still diversifying
A38: Stronger diversification benefit | B38: 0.3 | C38: ρ < | D38: Largely independent return drivers
A40: 5 · FORMATTING CONVENTIONS
A41: Blue font | B41: Hardcoded input or assumption — safe to edit
A42: Black font | B42: Formula calculated within the sheet
A43: Green font | B43: Link to another sheet in this workbook

Sheet Holdings
A1: HOLDINGS — PORTFOLIO CONSTRUCTION
A2: Model portfolio: 7 NSE-listed large caps across 7 sectors, held at fixed target weights. No personal purchase prices or units are assumed.
A4: 1 · HOLDINGS TABLE
A6: # | B6: Ticker | C6: Company | D6: Sector | E6: Target Weight | F6: Latest Price (₹) | G6: Period Return | H6: Annualised Return | I6: Initial Allocation (₹) | J6: Contribution to Period Return
A7: 1 | B7: RELIANCE.NS | C7: Reliance Industries | D7: Energy / Conglomerate | E7: 0.23 | F7: =INDEX(Prices!$B$4:$B$1000,COUNT(Prices!$A$4:$A$1000)) -> 1309.5 | G7: {=IFERROR(INDEX(Prices!$B$4:$B$1000,COUNT(Prices!$A$4:$A$1000))/Prices!$B$4-1,"")} -> -0.11077158 | H7: =Returns!B$1004 -> -0.035825572 | I7: =$E7*NotionalValue -> 230000 | J7: =$E7*$G7 -> -0.025477464
A8: 2 | B8: BHARTIARTL.NS | C8: Bharti Airtel | D8: Telecom | E8: 0.15 | F8: =INDEX(Prices!$C$4:$C$1000,COUNT(Prices!$A$4:$A$1000)) -> 1854 | G8: {=IFERROR(INDEX(Prices!$C$4:$C$1000,COUNT(Prices!$A$4:$A$1000))/Prices!$C$4-1,"")} -> 0.13432653 | H8: =Returns!C$1004 -> 0.081444945 | I8: =$E8*NotionalValue -> 150000 | J8: =$E8*$G8 -> 0.02014898
A9: 3 | B9: HDFCBANK.NS | C9: HDFC Bank | D9: Banking | E9: 0.15 | F9: =INDEX(Prices!$D$4:$D$1000,COUNT(Prices!$A$4:$A$1000)) -> 710.5 | G9: {=IFERROR(INDEX(Prices!$D$4:$D$1000,COUNT(Prices!$A$4:$A$1000))/Prices!$D$4-1,"")} -> -0.14491258 | H9: =Returns!D$1004 -> -0.060606364 | I9: =$E9*NotionalValue -> 150000 | J9: =$E9*$G9 -> -0.021736888
A10: 4 | B10: LT.NS | C10: Larsen & Toubro | D10: Industrials / Infrastructure | E10: 0.14 | F10: =INDEX(Prices!$E$4:$E$1000,COUNT(Prices!$A$4:$A$1000)) -> 3999 | G10: {=IFERROR(INDEX(Prices!$E$4:$E$1000,COUNT(Prices!$A$4:$A$1000))/Prices!$E$4-1,"")} -> 0.10683642 | H10: =Returns!E$1004 -> 0.084524854 | I10: =$E10*NotionalValue -> 140000 | J10: =$E10*$G10 -> 0.014957099
A11: 5 | B11: CIPLA.NS | C11: Cipla | D11: Pharmaceuticals | E11: 0.12 | F11: =INDEX(Prices!$F$4:$F$1000,COUNT(Prices!$A$4:$A$1000)) -> 1395 | G11: {=IFERROR(INDEX(Prices!$F$4:$F$1000,COUNT(Prices!$A$4:$A$1000))/Prices!$F$4-1,"")} -> -0.15948665 | H11: =Returns!F$1004 -> -0.069387743 | I11: =$E11*NotionalValue -> 120000 | J11: =$E11*$G11 -> -0.019138399
A12: 6 | B12: MARUTI.NS | C12: Maruti Suzuki | D12: Automobile | E12: 0.12 | F12: =INDEX(Prices!$G$4:$G$1000,COUNT(Prices!$A$4:$A$1000)) -> 12760 | G12: {=IFERROR(INDEX(Prices!$G$4:$G$1000,COUNT(Prices!$A$4:$A$1000))/Prices!$G$4-1,"")} -> 0.03604646 | H12: =Returns!G$1004 -> 0.04689393 | I12: =$E12*NotionalValue -> 120000 | J12: =$E12*$G12 -> 0.0043255752
A13: 7 | B13: HCLTECH.NS | C13: HCL Technologies | D13: Information Technology | E13: 0.09 | F13: =INDEX(Prices!$H$4:$H$1000,COUNT(Prices!$A$4:$A$1000)) -> 1282.8 | G13: {=IFERROR(INDEX(Prices!$H$4:$H$1000,COUNT(Prices!$A$4:$A$1000))/Prices!$H$4-1,"")} -> -0.28998685 | H13: =Returns!H$1004 -> -0.12948856 | I13: =$E13*NotionalValue -> 90000 | J13: =$E13*$G13 -> -0.026098816
B14: TOTAL PORTFOLIO | E14: =SUM(E7:E13) -> 1 | I14: =SUM(I7:I13) -> 1000000 | J14: =SUM(J7:J13) -> -0.053019912
B16: WEIGHT CHECK | D16: =SUM(WeightsCol) -> 1 | E16: =IF(ROUND(SUM(WeightsCol),6)=1,"✓ PASS — weights sum to exactly 100%","✗ FAIL — weights sum to "&TEXT(SUM(WeightsCol),"0.00%")&", must equal 100%") -> ✓ PASS — weights sum to exactly 100%
A18: 2 · SECTOR ALLOCATION
D19: Sector | E19: Holdings | F19: Weight | G19: Notional (₹)
D20: Energy / Conglomerate | E20: =COUNTIF($D$7:$D$13,$D20) -> 1 | F20: =SUMIF($D$7:$D$13,$D20,$E$7:$E$13) -> 0.23 | G20: =$F20*NotionalValue -> 230000
D21: Telecom | E21: =COUNTIF($D$7:$D$13,$D21) -> 1 | F21: =SUMIF($D$7:$D$13,$D21,$E$7:$E$13) -> 0.15 | G21: =$F21*NotionalValue -> 150000
D22: Banking | E22: =COUNTIF($D$7:$D$13,$D22) -> 1 | F22: =SUMIF($D$7:$D$13,$D22,$E$7:$E$13) -> 0.15 | G22: =$F22*NotionalValue -> 150000
D23: Industrials / Infrastructure | E23: =COUNTIF($D$7:$D$13,$D23) -> 1 | F23: =SUMIF($D$7:$D$13,$D23,$E$7:$E$13) -> 0.14 | G23: =$F23*NotionalValue -> 140000
D24: Pharmaceuticals | E24: =COUNTIF($D$7:$D$13,$D24) -> 1 | F24: =SUMIF($D$7:$D$13,$D24,$E$7:$E$13) -> 0.12 | G24: =$F24*NotionalValue -> 120000
D25: Automobile | E25: =COUNTIF($D$7:$D$13,$D25) -> 1 | F25: =SUMIF($D$7:$D$13,$D25,$E$7:$E$13) -> 0.12 | G25: =$F25*NotionalValue -> 120000
D26: Information Technology | E26: =COUNTIF($D$7:$D$13,$D26) -> 1 | F26: =SUMIF($D$7:$D$13,$D26,$E$7:$E$13) -> 0.09 | G26: =$F26*NotionalValue -> 90000
D27: TOTAL | E27: =SUM(E20:E26) -> 7 | F27: =SUM(F20:F26) -> 1 | G27: =SUM(G20:G26) -> 1000000
A29: 3 · MODEL QUALITY CHECKS
A30: # | B30: Check | G30: Value | I30: Result
A31: 1 | B31: Portfolio weights sum to exactly 100% | G31: =SUM(WeightsCol) -> 1 | I31: =IF(ROUND(SUM(WeightsCol),6)=1,"PASS","FAIL") -> PASS
A32: 2 | B32: All 7 holdings present | G32: =COUNTA($B$7:$B$13) -> 7 | I32: =IF(COUNTA($B$7:$B$13)=7,"PASS","FAIL") -> PASS
A33: 3 | B33: Price observations ≥ 100 (approx. 2 years weekly) | G33: =COUNT(Prices!$A$4:$A$1000) -> 105 | I33: =IF(COUNT(Prices!$A$4:$A$1000)>=100,"PASS","FAIL") -> PASS
A34: 4 | B34: No missing price observations within the populated window (blank cells) | G34: =COUNTBLANK(Prices!$B$4:$I$1000)-COUNTBLANK(Prices!$A$4:$A$1000)*8 -> 0 | I34: =IF(G34=0,"PASS","FAIL") -> PASS
A35: 5 | B35: Price dates aligned and strictly ascending | G35: {=SUMPRODUCT(--(Prices!$A$5:INDEX(Prices!$A$4:$A$1000,COUNT(Prices!$A$4:$A$1000))<=Prices!$A$4:INDEX(Prices!$A$4:$A$1000,COUNT(Prices!$A$4:$A$1000)-1)))} -> 0 | I35: =IF(G35=0,"PASS","FAIL") -> PASS
A36: 6 | B36: Return observations = price observations − 1 | G36: =COUNT(PortRet) -> 104 | I36: =IF(COUNT(PortRet)=COUNT(Prices!$A$4:$A$1000)-1,"PASS","FAIL") -> PASS
A37: 7 | B37: Benchmark observations aligned with portfolio | G37: =COUNT(BenchRet) -> 104 | I37: =IF(COUNT(BenchRet)=COUNT(PortRet),"PASS","FAIL") -> PASS
A38: 8 | B38: Portfolio return uses target weights (recomputed independently) | G38: =SUMPRODUCT(Weights,Returns!$B$6:$H$6)-Returns!$J$6 -> 0 | I38: =IF(ABS(SUMPRODUCT(Weights,Returns!$B$6:$H$6)-Returns!$J$6)<0.0000000001,"PASS","FAIL") -> PASS
A39: 9 | B39: Growth of ₹100 series both start at exactly 100 | G39: =Drawdown!$C$7+Drawdown!$G$7 -> 200 | I39: =IF(AND(Drawdown!$C$7=100,Drawdown!$G$7=100),"PASS","FAIL") -> PASS
A40: 10 | B40: Cumulative return reconciles to growth index | G40: =Risk_Analysis!$B$11-(INDEX(Drawdown!$C$8:$C$1000,COUNT(Drawdown!$A$8:$A$1000))/100-1) -> 0 | I40: =IF(ABS(Risk_Analysis!$B$11-(INDEX(Drawdown!$C$8:$C$1000,COUNT(Drawdown!$A$8:$A$1000))/100-1))<0.0000000001,"PASS","FAIL") -> PASS
A41: 11 | B41: Maximum drawdown is negative or zero | G41: =Risk_Analysis!$B$35 -> -0.17991189 | I41: =IF(Risk_Analysis!$B$35<=0,"PASS","FAIL") -> PASS
A42: 12 | B42: Correlation matrix diagonal equals 1.00 | G42: =SUM(Correlation!$B$7,Correlation!$C$8,Correlation!$D$9,Correlation!$E$10,Correlation!$F$11,Correlation!$G$12,Correlation!$H$13) -> 7 | I42: =IF(ROUND(SUM(Correlation!$B$7,Correlation!$C$8,Correlation!$D$9,Correlation!$E$10,Correlation!$F$11,Correlation!$G$12,Correlation!$H$13),6)=7,"PASS","FAIL") -> PASS
A43: 13 | B43: Correlation matrix symmetric (sum = 7 + 2 x sum of 21 unique pairs) | G43: =SUM(Correlation!$B$7:$H$13)-(7+2*SUM(Correlation!$F$17:$F$37)) -> 0 | I43: =IF(ABS(SUM(Correlation!$B$7:$H$13)-(7+2*SUM(Correlation!$F$17:$F$37)))<0.000001,"PASS","FAIL") -> PASS
A44: 14 | B44: Return contributions sum to portfolio annualised return | G44: =Contribution!$D$14 -> 0 | I44: =IF(ABS(Contribution!$D$14)<0.000001,"PASS","FAIL") -> PASS
A45: 15 | B45: Risk contributions sum to portfolio variance | G45: =Contribution!$E$36 -> 0 | I45: =IF(ABS(Contribution!$E$36)<0.0000001,"PASS","FAIL") -> PASS
...

Sheet Prices
A1: PRICES
A2: Ticker → | B2: RELIANCE.NS | C2: BHARTIARTL.NS | D2: HDFCBANK.NS | E2: LT.NS | F2: CIPLA.NS | G2: MARUTI.NS | H2: HCLTECH.NS | I2: ^NSEI
A3: Date | B3: Reliance Industries | C3: Bharti Airtel | D3: HDFC Bank | E3: Larsen & Toubro | F3: Cipla | G3: Maruti Suzuki | H3: HCL Technologies | I3: NIFTY 50
A4: =(TODAY()-730)-WEEKDAY(TODAY()-730,2)+1 -> 45544 | B4: =IF($A4="","",IFERROR(INDEX(Market_Data!$C$21:$C$613,MATCH($A4,Market_Data!$B$21:INDEX(Market_Data!$B$21:$B$613,COUNT(Market_Data!$B$21:$B$613)),1)),"")) -> 1472.625 | C4: =IF($A4="","",IFERROR(INDEX(Market_Data!$F$21:$F$613,MATCH($A4,Market_Data!$E$21:INDEX(Market_Data!$E$21:$E$613,COUNT(Market_Data!$E$21:$E$613)),1)),"")) -> 1634.45 | D4: =IF($A4="","",IFERROR(INDEX(Market_Data!$I$21:$I$613,MATCH($A4,Market_Data!$H$21:INDEX(Market_Data!$H$21:$H$613,COUNT(Market_Data!$H$21:$H$613)),1)),"")) -> 830.9092 | E4: =IF($A4="","",IFERROR(INDEX(Market_Data!$L$21:$L$613,MATCH($A4,Market_Data!$K$21:INDEX(Market_Data!$K$21:$K$613,COUNT(Market_Data!$K$21:$K$613)),1)),"")) -> 3613 | F4: =IF($A4="","",IFERROR(INDEX(Market_Data!$O$21:$O$613,MATCH($A4,Market_Data!$N$21:INDEX(Market_Data!$N$21:$N$613,COUNT(Market_Data!$N$21:$N$613)),1)),"")) -> 1659.7 | G4: =IF($A4="","",IFERROR(INDEX(Market_Data!$R$21:$R$613,MATCH($A4,Market_Data!$Q$21:INDEX(Market_Data!$Q$21:$Q$613,COUNT(Market_Data!$Q$21:$Q$613)),1)),"")) -> 12316.05 | H4: =IF($A4="","",IFERROR(INDEX(Market_Data!$U$21:$U$613,MATCH($A4,Market_Data!$T$21:INDEX(Market_Data!$T$21:$T$613,COUNT(Market_Data!$T$21:$T$613)),1)),"")) -> 1806.7271 | I4: =IF($A4="","",IFERROR(INDEX(Query1[Close],MATCH($A4,Query1[Date],1)),"")) -> 24936.4
A5: =IF($A4="","",IF($A4+7<=TODAY(),$A4+7,"")) -> 45551 | B5: =IF($A5="","",IFERROR(INDEX(Market_Data!$C$21:$C$613,MATCH($A5,Market_Data!$B$21:INDEX(Market_Data!$B$21:$B$613,COUNT(Market_Data!$B$21:$B$613)),1)),"")) -> 1485.925 | C5: =IF($A5="","",IFERROR(INDEX(Market_Data!$F$21:$F$613,MATCH($A5,Market_Data!$E$21:INDEX(Market_Data!$E$21:$E$613,COUNT(Market_Data!$E$21:$E$613)),1)),"")) -> 1711.75 | D5: =IF($A5="","",IFERROR(INDEX(Market_Data!$I$21:$I$613,MATCH($A5,Market_Data!$H$21:INDEX(Market_Data!$H$21:$H$613,COUNT(Market_Data!$H$21:$H$613)),1)),"")) -> 868.4409 | E5: =IF($A5="","",IFERROR(INDEX(Market_Data!$L$21:$L$613,MATCH($A5,Market_Data!$K$21:INDEX(Market_Data!$K$21:$K$613,COUNT(Market_Data!$K$21:$K$613)),1)),"")) -> 3793.9 | F5: =IF($A5="","",IFERROR(INDEX(Market_Data!$O$21:$O$613,MATCH($A5,Market_Data!$N$21:INDEX(Market_Data!$N$21:$N$613,COUNT(Market_Data!$N$21:$N$613)),1)),"")) -> 1638.65 | G5: =IF($A5="","",IFERROR(INDEX(Market_Data!$R$21:$R$613,MATCH($A5,Market_Data!$Q$21:INDEX(Market_Data!$Q$21:$Q$613,COUNT(Market_Data!$Q$21:$Q$613)),1)),"")) -> 12614.5 | H5: =IF($A5="","",IFERROR(INDEX(Market_Data!$U$21:$U$613,MATCH($A5,Market_Data!$T$21:INDEX(Market_Data!$T$21:$T$613,COUNT(Market_Data!$T$21:$T$613)),1)),"")) -> 1754.1538 | I5: =IF($A5="","",IFERROR(INDEX(Query1[Close],MATCH($A5,Query1[Date],1)),"")) -> 25383.75
A6: =IF($A5="","",IF($A5+7<=TODAY(),$A5+7,"")) -> 45558 | B6: =IF($A6="","",IFERROR(INDEX(Market_Data!$C$21:$C$613,MATCH($A6,Market_Data!$B$21:INDEX(Market_Data!$B$21:$B$613,COUNT(Market_Data!$B$21:$B$613)),1)),"")) -> 1526.175 | C6: =IF($A6="","",IFERROR(INDEX(Market_Data!$F$21:$F$613,MATCH($A6,Market_Data!$E$21:INDEX(Market_Data!$E$21:$E$613,COUNT(Market_Data!$E$21:$E$613)),1)),"")) -> 1734.6 | D6: =IF($A6="","",IFERROR(INDEX(Market_Data!$I$21:$I$613,MATCH($A6,Market_Data!$H$21:INDEX(Market_Data!$H$21:$H$613,COUNT(Market_Data!$H$21:$H$613)),1)),"")) -> 874.1517 | E6: =IF($A6="","",IFERROR(INDEX(Market_Data!$L$21:$L$613,MATCH($A6,Market_Data!$K$21:INDEX(Market_Data!$K$21:$K$613,COUNT(Market_Data!$K$21:$K$613)),1)),"")) -> 3705.65 | F6: =IF($A6="","",IFERROR(INDEX(Market_Data!$O$21:$O$613,MATCH($A6,Market_Data!$N$21:INDEX(Market_Data!$N$21:$N$613,COUNT(Market_Data!$N$21:$N$613)),1)),"")) -> 1672.5 | G6: =IF($A6="","",IFERROR(INDEX(Market_Data!$R$21:$R$613,MATCH($A6,Market_Data!$Q$21:INDEX(Market_Data!$Q$21:$Q$613,COUNT(Market_Data!$Q$21:$Q$613)),1)),"")) -> 13495.6 | H6: =IF($A6="","",IFERROR(INDEX(Market_Data!$U$21:$U$613,MATCH($A6,Market_Data!$T$21:INDEX(Market_Data!$T$21:$T$613,COUNT(Market_Data!$T$21:$T$613)),1)),"")) -> 1802.3419 | I6: =IF($A6="","",IFERROR(INDEX(Query1[Close],MATCH($A6,Query1[Date],1)),"")) -> 25939.051
A7: =IF($A6="","",IF($A6+7<=TODAY(),$A6+7,"")) -> 45565 | B7: =IF($A7="","",IFERROR(INDEX(Market_Data!$C$21:$C$613,MATCH($A7,Market_Data!$B$21:INDEX(Market_Data!$B$21:$B$613,COUNT(Market_Data!$B$21:$B$613)),1)),"")) -> 1386.525 | C7: =IF($A7="","",IFERROR(INDEX(Market_Data!$F$21:$F$613,MATCH($A7,Market_Data!$E$21:INDEX(Market_Data!$E$21:$E$613,COUNT(Market_Data!$E$21:$E$613)),1)),"")) -> 1640.9 | D7: =IF($A7="","",IFERROR(INDEX(Market_Data!$I$21:$I$613,MATCH($A7,Market_Data!$H$21:INDEX(Market_Data!$H$21:$H$613,COUNT(Market_Data!$H$21:$H$613)),1)),"")) -> 826.7695 | E7: =IF($A7="","",IFERROR(INDEX(Market_Data!$L$21:$L$613,MATCH($A7,Market_Data!$K$21:INDEX(Market_Data!$K$21:$K$613,COUNT(Market_Data!$K$21:$K$613)),1)),"")) -> 3493.95 | F7: =IF($A7="","",IFERROR(INDEX(Market_Data!$O$21:$O$613,MATCH($A7,Market_Data!$N$21:INDEX(Market_Data!$N$21:$N$613,COUNT(Market_Data!$N$21:$N$613)),1)),"")) -> 1623.3 | G7: =IF($A7="","",IFERROR(INDEX(Market_Data!$R$21:$R$613,MATCH($A7,Market_Data!$Q$21:INDEX(Market_Data!$Q$21:$Q$613,COUNT(Market_Data!$Q$21:$Q$613)),1)),"")) -> 12605.75 | H7: =IF($A7="","",IFERROR(INDEX(Market_Data!$U$21:$U$613,MATCH($A7,Market_Data!$T$21:INDEX(Market_Data!$T$21:$T$613,COUNT(Market_Data!$T$21:$T$613)),1)),"")) -> 1770.6484 | I7: =IF($A7="","",IFERROR(INDEX(Query1[Close],MATCH($A7,Query1[Date],1)),"")) -> 25810.85
A8: =IF($A7="","",IF($A7+7<=TODAY(),$A7+7,"")) -> 45572 | B8: =IF($A8="","",IFERROR(INDEX(Market_Data!$C$21:$C$613,MATCH($A8,Market_Data!$B$21:INDEX(Market_Data!$B$21:$B$613,COUNT(Market_Data!$B$21:$B$613)),1)),"")) -> 1372.1 | C8: =IF($A8="","",IFERROR(INDEX(Market_Data!$F$21:$F$613,MATCH($A8,Market_Data!$E$21:INDEX(Market_Data!$E$21:$E$613,COUNT(Market_Data!$E$21:$E$613)),1)),"")) -> 1687.4 | D8: =IF($A8="","",IFERROR(INDEX(Market_Data!$I$21:$I$613,MATCH($A8,Market_Data!$H$21:INDEX(Market_Data!$H$21:$H$613,COUNT(Market_Data!$H$21:$H$613)),1)),"")) -> 823.4528 | E8: =IF($A8="","",IFERROR(INDEX(Market_Data!$L$21:$L$613,MATCH($A8,Market_Data!$K$21:INDEX(Market_Data!$K$21:$K$613,COUNT(Market_Data!$K$21:$K$613)),1)),"")) -> 3482.55 | F8: =IF($A8="","",IFERROR(INDEX(Market_Data!$O$21:$O$613,MATCH($A8,Market_Data!$N$21:INDEX(Market_Data!$N$21:$N$613,COUNT(Market_Data!$N$21:$N$613)),1)),"")) -> 1595.75 | G8: =IF($A8="","",IFERROR(INDEX(Market_Data!$R$21:$R$613,MATCH($A8,Market_Data!$Q$21:INDEX(Market_Data!$Q$21:$Q$613,COUNT(Market_Data!$Q$21:$Q$613)),1)),"")) -> 12776.65 | H8: =IF($A8="","",IFERROR(INDEX(Market_Data!$U$21:$U$613,MATCH($A8,Market_Data!$T$21:INDEX(Market_Data!$T$21:$T$613,COUNT(Market_Data!$T$21:$T$613)),1)),"")) -> 1833.4872 | I8: =IF($A8="","",IFERROR(INDEX(Query1[Close],MATCH($A8,Query1[Date],1)),"")) -> 24795.75
A9: =IF($A8="","",IF($A8+7<=TODAY(),$A8+7,"")) -> 45579 | B9: =IF($A9="","",IFERROR(INDEX(Market_Data!$C$21:$C$613,MATCH($A9,Market_Data!$B$21:INDEX(Market_Data!$B$21:$B$613,COUNT(Market_Data!$B$21:$B$613)),1)),"")) -> 1359.3 | C9: =IF($A9="","",IFERROR(INDEX(Market_Data!$F$21:$F$613,MATCH($A9,Market_Data!$E$21:INDEX(Market_Data!$E$21:$E$613,COUNT(Market_Data!$E$21:$E$613)),1)),"")) -> 1707.85 | D9: =IF($A9="","",IFERROR(INDEX(Market_Data!$I$21:$I$613,MATCH($A9,Market_Data!$H$21:INDEX(Market_Data!$H$21:$H$613,COUNT(Market_Data!$H$21:$H$613)),1)),"")) -> 838.8395 | E9: =IF($A9="","",IFERROR(INDEX(Market_Data!$L$21:$L$613,MATCH($A9,Market_Data!$K$21:INDEX(Market_Data!$K$21:$K$613,COUNT(Market_Data!$K$21:$K$613)),1)),"")) -> 3577.8 | F9: =IF($A9="","",IFERROR(INDEX(Market_Data!$O$21:$O$613,MATCH($A9,Market_Data!$N$21:INDEX(Market_Data!$N$21:$N$613,COUNT(Market_Data!$N$21:$N$613)),1)),"")) -> 1551.7 | G9: =IF($A9="","",IFERROR(INDEX(Market_Data!$R$21:$R$613,MATCH($A9,Market_Data!$Q$21:INDEX(Market_Data!$Q$21:$Q$613,COUNT(Market_Data!$Q$21:$Q$613)),1)),"")) -> 12105.1 | H9: =IF($A9="","",IFERROR(INDEX(Market_Data!$U$21:$U$613,MATCH($A9,Market_Data!$T$21:INDEX(Market_Data!$T$21:$T$613,COUNT(Market_Data!$T$21:$T$613)),1)),"")) -> 1851.4767 | I9: =IF($A9="","",IFERROR(INDEX(Query1[Close],MATCH($A9,Query1[Date],1)),"")) -> 25127.949
A10: =IF($A9="","",IF($A9+7<=TODAY(),$A9+7,"")) -> 45586 | B10: =IF($A10="","",IFERROR(INDEX(Market_Data!$C$21:$C$613,MATCH($A10,Market_Data!$B$21:INDEX(Market_Data!$B$21:$B$613,COUNT(Market_Data!$B$21:$B$613)),1)),"")) -> 1327.85 | C10: =IF($A10="","",IFERROR(INDEX(Market_Data!$F$21:$F$613,MATCH($A10,Market_Data!$E$21:INDEX(Market_Data!$E$21:$E$613,COUNT(Market_Data!$E$21:$E$613)),1)),"")) -> 1666 | D10: =IF($A10="","",IFERROR(INDEX(Market_Data!$I$21:$I$613,MATCH($A10,Market_Data!$H$21:INDEX(Market_Data!$H$21:$H$613,COUNT(Market_Data!$H$21:$H$613)),1)),"")) -> 869.5382 | E10: =IF($A10="","",IFERROR(INDEX(Market_Data!$L$21:$L$613,MATCH($A10,Market_Data!$K$21:INDEX(Market_Data!$K$21:$K$613,COUNT(Market_Data!$K$21:$K$613)),1)),"")) -> 3326.4 | F10: =IF($A10="","",IFERROR(INDEX(Market_Data!$O$21:$O$613,MATCH($A10,Market_Data!$N$21:INDEX(Market_Data!$N$21:$N$613,COUNT(Market_Data!$N$21:$N$613)),1)),"")) -> 1488.9 | G10: =IF($A10="","",IFERROR(INDEX(Market_Data!$R$21:$R$613,MATCH($A10,Market_Data!$Q$21:INDEX(Market_Data!$Q$21:$Q$613,COUNT(Market_Data!$Q$21:$Q$613)),1)),"")) -> 11502.85 | H10: =IF($A10="","",IFERROR(INDEX(Market_Data!$U$21:$U$613,MATCH($A10,Market_Data!$T$21:INDEX(Market_Data!$T$21:$T$613,COUNT(Market_Data!$T$21:$T$613)),1)),"")) -> 1846.1446 | I10: =IF($A10="","",IFERROR(INDEX(Query1[Close],MATCH($A10,Query1[Date],1)),"")) -> 24781.1
A11: =IF($A10="","",IF($A10+7<=TODAY(),$A10+7,"")) -> 45593 | B11: =IF($A11="","",IFERROR(INDEX(Market_Data!$C$21:$C$613,MATCH($A11,Market_Data!$B$21:INDEX(Market_Data!$B$21:$B$613,COUNT(Market_Data!$B$21:$B$613)),1)),"")) -> 1338.65 | C11: =IF($A11="","",IFERROR(INDEX(Market_Data!$F$21:$F$613,MATCH($A11,Market_Data!$E$21:INDEX(Market_Data!$E$21:$E$613,COUNT(Market_Data!$E$21:$E$613)),1)),"")) -> 1616.45 | D11: =IF($A11="","",IFERROR(INDEX(Market_Data!$I$21:$I$613,MATCH($A11,Market_Data!$H$21:INDEX(Market_Data!$H$21:$H$613,COUNT(Market_Data!$H$21:$H$613)),1)),"")) -> 866.4957 | E11: =IF($A11="","",IFERROR(INDEX(Market_Data!$L$21:$L$613,MATCH($A11,Market_Data!$K$21:INDEX(Market_Data!$K$21:$K$613,COUNT(Market_Data!$K$21:$K$613)),1)),"")) -> 3626.35 | F11: =IF($A11="","",IFERROR(INDEX(Market_Data!$O$21:$O$613,MATCH($A11,Market_Data!$N$21:INDEX(Market_Data!$N$21:$N$613,COUNT(Market_Data!$N$21:$N$613)),1)),"")) -> 1559.55 | G11: =IF($A11="","",IFERROR(INDEX(Market_Data!$R$21:$R$613,MATCH($A11,Market_Data!$Q$21:INDEX(Market_Data!$Q$21:$Q$613,COUNT(Market_Data!$Q$21:$Q$613)),1)),"")) -> 11110 | H11: =IF($A11="","",IFERROR(INDEX(Market_Data!$U$21:$U$613,MATCH($A11,Market_Data!$T$21:INDEX(Market_Data!$T$21:$T$613,COUNT(Market_Data!$T$21:$T$613)),1)),"")) -> 1751.5127 | I11: =IF($A11="","",IFERROR(INDEX(Query1[Close],MATCH($A11,Query1[Date],1)),"")) -> 24339.15
A12: =IF($A11="","",IF($A11+7<=TODAY(),$A11+7,"")) -> 45600 | B12: =IF($A12="","",IFERROR(INDEX(Market_Data!$C$21:$C$613,MATCH($A12,Market_Data!$B$21:INDEX(Market_Data!$B$21:$B$613,COUNT(Market_Data!$B$21:$B$613)),1)),"")) -> 1283.75 | C12: =IF($A12="","",IFERROR(INDEX(Market_Data!$F$21:$F$613,MATCH($A12,Market_Data!$E$21:INDEX(Market_Data!$E$21:$E$613,COUNT(Market_Data!$E$21:$E$613)),1)),"")) -> 1569.9 | D12: =IF($A12="","",IFERROR(INDEX(Market_Data!$I$21:$I$613,MATCH($A12,Market_Data!$H$21:INDEX(Market_Data!$H$21:$H$613,COUNT(Market_Data!$H$21:$H$613)),1)),"")) -> 875.0495 | E12: =IF($A12="","",IFERROR(INDEX(Market_Data!$L$21:$L$613,MATCH($A12,Market_Data!$K$21:INDEX(Market_Data!$K$21:$K$613,COUNT(Market_Data!$K$21:$K$613)),1)),"")) -> 3660.3 | F12: =IF($A12="","",IFERROR(INDEX(Market_Data!$O$21:$O$613,MATCH($A12,Market_Data!$N$21:INDEX(Market_Data!$N$21:$N$613,COUNT(Market_Data!$N$21:$N$613)),1)),"")) -> 1592.6 | G12: =IF($A12="","",IFERROR(INDEX(Market_Data!$R$21:$R$613,MATCH($A12,Market_Data!$Q$21:INDEX(Market_Data!$Q$21:$Q$613,COUNT(Market_Data!$Q$21:$Q$613)),1)),"")) -> 11303 | H12: =IF($A12="","",IFERROR(INDEX(Market_Data!$U$21:$U$613,MATCH($A12,Market_Data!$T$21:INDEX(Market_Data!$T$21:$T$613,COUNT(Market_Data!$T$21:$T$613)),1)),"")) -> 1831.3444 | I12: =IF($A12="","",IFERROR(INDEX(Query1[Close],MATCH($A12,Query1[Date],1)),"")) -> 23995.35
A13: =IF($A12="","",IF($A12+7<=TODAY(),$A12+7,"")) -> 45607 | B13: =IF($A13="","",IFERROR(INDEX(Market_Data!$C$21:$C$613,MATCH($A13,Market_Data!$B$21:INDEX(Market_Data!$B$21:$B$613,COUNT(Market_Data!$B$21:$B$613)),1)),"")) -> 1267.6 | C13: =IF($A13="","",IFERROR(INDEX(Market_Data!$F$21:$F$613,MATCH($A13,Market_Data!$E$21:INDEX(Market_Data!$E$21:$E$613,COUNT(Market_Data!$E$21:$E$613)),1)),"")) -> 1550.5 | D13: =IF($A13="","",IFERROR(INDEX(Market_Data!$I$21:$I$613,MATCH($A13,Market_Data!$H$21:INDEX(Market_Data!$H$21:$H$613,COUNT(Market_Data!$H$21:$H$613)),1)),"")) -> 844.276 | E13: =IF($A13="","",IFERROR(INDEX(Market_Data!$L$21:$L$613,MATCH($A13,Market_Data!$K$21:INDEX(Market_Data!$K$21:$K$613,COUNT(Market_Data!$K$21:$K$613)),1)),"")) -> 3526.25 | F13: =IF($A13="","",IFERROR(INDEX(Market_Data!$O$21:$O$613,MATCH($A13,Market_Data!$N$21:INDEX(Market_Data!$N$21:$N$613,COUNT(Market_Data!$N$21:$N$613)),1)),"")) -> 1499.75 | G13: =IF($A13="","",IFERROR(INDEX(Market_Data!$R$21:$R$613,MATCH($A13,Market_Data!$Q$21:INDEX(Market_Data!$Q$21:$Q$613,COUNT(Market_Data!$Q$21:$Q$613)),1)),"")) -> 11006.05 | H13: =IF($A13="","",IFERROR(INDEX(Market_Data!$U$21:$U$613,MATCH($A13,Market_Data!$T$21:INDEX(Market_Data!$T$21:$T$613,COUNT(Market_Data!$T$21:$T$613)),1)),"")) -> 1852.7225 | I13: =IF($A13="","",IFERROR(INDEX(Query1[Close],MATCH($A13,Query1[Date],1)),"")) -> 24141.301
A14: =IF($A13="","",IF($A13+7<=TODAY(),$A13+7,"")) -> 45614 | B14: =IF($A14="","",IFERROR(INDEX(Market_Data!$C$21:$C$613,MATCH($A14,Market_Data!$B$21:INDEX(Market_Data!$B$21:$B$613,COUNT(Market_Data!$B$21:$B$613)),1)),"")) -> 1265.4 | C14: =IF($A14="","",IFERROR(INDEX(Market_Data!$F$21:$F$613,MATCH($A14,Market_Data!$E$21:INDEX(Market_Data!$E$21:$E$613,COUNT(Market_Data!$E$21:$E$613)),1)),"")) -> 1569.3 | D14: =IF($A14="","",IFERROR(INDEX(Market_Data!$I$21:$I$613,MATCH($A14,Market_Data!$H$21:INDEX(Market_Data!$H$21:$H$613,COUNT(Market_Data!$H$21:$H$613)),1)),"")) -> 870.6355 | E14: =IF($A14="","",IFERROR(INDEX(Market_Data!$L$21:$L$613,MATCH($A14,Market_Data!$K$21:INDEX(Market_Data!$K$21:$K$613,COUNT(Market_Data!$K$21:$K$613)),1)),"")) -> 3603.5 | F14: =IF($A14="","",IFERROR(INDEX(Market_Data!$O$21:$O$613,MATCH($A14,Market_Data!$N$21:INDEX(Market_Data!$N$21:$N$613,COUNT(Market_Data!$N$21:$N$613)),1)),"")) -> 1486.5 | G14: =IF($A14="","",IFERROR(INDEX(Market_Data!$R$21:$R$613,MATCH($A14,Market_Data!$Q$21:INDEX(Market_Data!$Q$21:$Q$613,COUNT(Market_Data!$Q$21:$Q$613)),1)),"")) -> 11063.6 | H14: =IF($A14="","",IFERROR(INDEX(Market_Data!$U$21:$U$613,MATCH($A14,Market_Data!$T$21:INDEX(Market_Data!$T$21:$T$613,COUNT(Market_Data!$T$21:$T$613)),1)),"")) -> 1892.0404 | I14: =IF($A14="","",IFERROR(INDEX(Query1[Close],MATCH($A14,Query1[Date],1)),"")) -> 23453.801
A15: =IF($A14="","",IF($A14+7<=TODAY(),$A14+7,"")) -> 45621 | B15: =IF($A15="","",IFERROR(INDEX(Market_Data!$C$21:$C$613,MATCH($A15,Market_Data!$B$21:INDEX(Market_Data!$B$21:$B$613,COUNT(Market_Data!$B$21:$B$613)),1)),"")) -> 1292.2 | C15: =IF($A15="","",IFERROR(INDEX(Market_Data!$F$21:$F$613,MATCH($A15,Market_Data!$E$21:INDEX(Market_Data!$E$21:$E$613,COUNT(Market_Data!$E$21:$E$613)),1)),"")) -> 1627.15 | D15: =IF($A15="","",IFERROR(INDEX(Market_Data!$I$21:$I$613,MATCH($A15,Market_Data!$H$21:INDEX(Market_Data!$H$21:$H$613,COUNT(Market_Data!$H$21:$H$613)),1)),"")) -> 895.7979 | E15: =IF($A15="","",IFERROR(INDEX(Market_Data!$L$21:$L$613,MATCH($A15,Market_Data!$K$21:INDEX(Market_Data!$K$21:$K$613,COUNT(Market_Data!$K$21:$K$613)),1)),"")) -> 3724.8 | F15: =IF($A15="","",IFERROR(INDEX(Market_Data!$O$21:$O$613,MATCH($A15,Market_Data!$N$21:INDEX(Market_Data!$N$21:$N$613,COUNT(Market_Data!$N$21:$N$613)),1)),"")) -> 1533.9 | G15: =IF($A15="","",IFERROR(INDEX(Market_Data!$R$21:$R$613,MATCH($A15,Market_Data!$Q$21:INDEX(Market_Data!$Q$21:$Q$613,COUNT(Market_Data!$Q$21:$Q$613)),1)),"")) -> 11074.2 | H15: =IF($A15="","",IFERROR(INDEX(Market_Data!$U$21:$U$613,MATCH($A15,Market_Data!$T$21:INDEX(Market_Data!$T$21:$T$613,COUNT(Market_Data!$T$21:$T$613)),1)),"")) -> 1841.859 | I15: =IF($A15="","",IFERROR(INDEX(Query1[Close],MATCH($A15,Query1[Date],1)),"")) -> 24221.9
A16: =IF($A15="","",IF($A15+7<=TODAY(),$A15+7,"")) -> 45628 | B16: =IF($A16="","",IFERROR(INDEX(Market_Data!$C$21:$C$613,MATCH($A16,Market_Data!$B$21:INDEX(Market_Data!$B$21:$B$613,COUNT(Market_Data!$B$21:$B$613)),1)),"")) -> 1311.55 | C16: =IF($A16="","",IFERROR(INDEX(Market_Data!$F$21:$F$613,MATCH($A16,Market_Data!$E$21:INDEX(Market_Data!$E$21:$E$613,COUNT(Market_Data!$E$21:$E$613)),1)),"")) -> 1597.85 | D16: =IF($A16="","",IFERROR(INDEX(Market_Data!$I$21:$I$613,MATCH($A16,Market_Data!$H$21:INDEX(Market_Data!$H$21:$H$613,COUNT(Market_Data!$H$21:$H$613)),1)),"")) -> 925.6237 | E16: =IF($A16="","",IFERROR(INDEX(Market_Data!$L$21:$L$613,MATCH($A16,Market_Data!$K$21:INDEX(Market_Data!$K$21:$K$613,COUNT(Market_Data!$K$21:$K$613)),1)),"")) -> 3866.7 | F16: =IF($A16="","",IFERROR(INDEX(Market_Data!$O$21:$O$613,MATCH($A16,Market_Data!$N$21:INDEX(Market_Data!$N$21:$N$613,COUNT(Market_Data!$N$21:$N$613)),1)),"")) -> 1477.4 | G16: =IF($A16="","",IFERROR(INDEX(Market_Data!$R$21:$R$613,MATCH($A16,Market_Data!$Q$21:INDEX(Market_Data!$Q$21:$Q$613,COUNT(Market_Data!$Q$21:$Q$613)),1)),"")) -> 11317.95 | H16: =IF($A16="","",IFERROR(INDEX(Market_Data!$U$21:$U$613,MATCH($A16,Market_Data!$T$21:INDEX(Market_Data!$T$21:$T$613,COUNT(Market_Data!$T$21:$T$613)),1)),"")) -> 1916.259 | I16: =IF($A16="","",IFERROR(INDEX(Query1[Close],MATCH($A16,Query1[Date],1)),"")) -> 24276.051
... A1000: =IF($A999="","",IF($A999+7<=TODAY(),$A999+7,"")) | B1000: =IF($A1000="","",IFERROR(INDEX(Market_Data!$C$21:$C$613,MATCH($A1000,Market_Data!$B$21:INDEX(Market_Data!$B$21:$B$613,COUNT(Market_Data!$B$21:$B$613)),1)),"")) | C1000: =IF($A1000="","",IFERROR(INDEX(Market_Data!$F$21:$F$613,MATCH($A1000,Market_Data!$E$21:INDEX(Market_Data!$E$21:$E$613,COUNT(Market_Data!$E$21:$E$613)),1)),"")) | D1000: =IF($A1000="","",IFERROR(INDEX(Market_Data!$I$21:$I$613,MATCH($A1000,Market_Data!$H$21:INDEX(Market_Data!$H$21:$H$613,COUNT(Market_Data!$H$21:$H$613)),1)),"")) | E1000: =IF($A1000="","",IFERROR(INDEX(Market_Data!$L$21:$L$613,MATCH($A1000,Market_Data!$K$21:INDEX(Market_Data!$K$21:$K$613,COUNT(Market_Data!$K$21:$K$613)),1)),"")) | F1000: =IF($A1000="","",IFERROR(INDEX(Market_Data!$O$21:$O$613,MATCH($A1000,Market_Data!$N$21:INDEX(Market_Data!$N$21:$N$613,COUNT(Market_Data!$N$21:$N$613)),1)),"")) | G1000: =IF($A1000="","",IFERROR(INDEX(Market_Data!$R$21:$R$613,MATCH($A1000,Market_Data!$Q$21:INDEX(Market_Data!$Q$21:$Q$613,COUNT(Market_Data!$Q$21:$Q$613)),1)),"")) | H1000: =IF($A1000="","",IFERROR(INDEX(Market_Data!$U$21:$U$613,MATCH($A1000,Market_Data!$T$21:INDEX(Market_Data!$T$21:$T$613,COUNT(Market_Data!$T$21:$T$613)),1)),"")) | I1000: =IF($A1000="","",IFERROR(INDEX(Query1[Close],MATCH($A1000,Query1[Date],1)),""))
A1002: ="Data-quality check: "&COUNT($A$4:$A$1000)&" weekly observations populated (formulas live through row 1000) · Blank price cells within populated window: "&(COUNTBLANK($B$4:$I$1000)-COUNTBLANK($A$4:$A$1000)*8)&" · "&IF((COUNTBLANK($B$4:$I$1000)-COUNTBLANK($A$4:$A$1000)*8)=0,"OK — no gaps within the populated window","REVIEW — some securities missing data within the populated window") -> Data-quality check: 105 weekly observations populated (formulas live through row 1000) · Blank price cells within populated window: 0 · OK — no gaps within the populated window

Sheet Market_Data
A1: MARKET DATA — DYNAMIC PRICE FEED (STOCKHISTORY)
A2: Every live price in this workbook is pulled here, once, via Excel's STOCKHISTORY function. Prices reads from this sheet through lookup formulas — no raw spill range is ever referenced directly by an analytical sheet.
A3: REQUIRES Microsoft Excel 365 (Windows/Mac) with an active Microsoft 365 subscription + internet access. STOCKHISTORY will show blank in LibreOffice, Google Sheets, older Excel, or Excel without a signed-in Microsoft 365 account — that is expected, not a bug.
A5: 1 · SECURITY IDENTIFIERS
A6: Edit the STOCKHISTORY identifier below and re-open if a security fails to resolve. Identifiers use the XNSE: MIC-code prefix — the National Stock Exchange of India's ISO 10383 exchange code — the same convention you personally confirmed works for XNSE:RELIANCE. Note: the 7 live stock formulas in Section 2 use each identifier typed directly into the formula (this is the exact form that resolved successfully for you), not a cell reference — if a feed ever needs a new identifier, edit its STOCKHISTORY formula in Section 2 directly. NIFTY 50 is no longer part of this STOCKHISTORY table at all — see Section 3 for how it's sourced now.
A8: Company | C8: Model ticker (.NS) | D8: STOCKHISTORY identifier | F8: Confidence / status
A9: Reliance Industries | C9: RELIANCE.NS | D9: XNSE:RELIANCE | F9: CONFIRMED — you personally tested this exact identifier in Excel.
A10: Bharti Airtel | C10: BHARTIARTL.NS | D10: XNSE:BHARTIARTL | F10: CONFIRMED — resolved successfully with real data in your Excel (105 weekly observations through 07-Sep-2026, verified before this update). Re-verify after any long gap without opening the file.
A11: HDFC Bank | C11: HDFCBANK.NS | D11: XNSE:HDFCBANK | F11: CONFIRMED — resolved successfully with real data in your Excel (105 weekly observations through 07-Sep-2026, verified before this update). Re-verify after any long gap without opening the file.
A12: Larsen & Toubro | C12: LT.NS | D12: XNSE:LT | F12: CONFIRMED — resolved successfully with real data in your Excel (105 weekly observations through 07-Sep-2026, verified before this update). Re-verify after any long gap without opening the file.
A13: Cipla | C13: CIPLA.NS | D13: XNSE:CIPLA | F13: CONFIRMED — resolved successfully with real data in your Excel (105 weekly observations through 07-Sep-2026, verified before this update). Re-verify after any long gap without opening the file.
A14: Maruti Suzuki | C14: MARUTI.NS | D14: XNSE:MARUTI | F14: CONFIRMED — resolved successfully with real data in your Excel (105 weekly observations through 07-Sep-2026, verified before this update). Re-verify after any long gap without opening the file.
A15: HCL Technologies | C15: HCLTECH.NS | D15: XNSE:HCLTECH | F15: CONFIRMED — resolved successfully with real data in your Excel (105 weekly observations through 07-Sep-2026, verified before this update). Re-verify after any long gap without opening the file.
A16: NIFTY 50 | C16: NIFTY 50 | D16: Power Query / Yahoo Finance
A17: 2 · LIVE STOCKHISTORY FEEDS (rolling ~2 years, weekly interval, Date + Close)
A18: STOCKHISTORY(identifier, TODAY()-730, TODAY(), 1, 1, 0, 1) · 1=weekly interval · 1=show headers · 0,1 = Date, Close. Each block spills downward from its anchor cell — do not type anything else into these columns below this point; leave the space empty so the spill has room to grow.
B19: Reliance Industries | E19: Bharti Airtel | H19: HDFC Bank | K19: Larsen & Toubro | N19: Cipla | Q19: Maruti Suzuki | T19: HCL Technologies | W19: NIFTY 50
B20: {=_xlfn.STOCKHISTORY("XNSE:RELIANCE",TODAY()-730,TODAY(),1,1,0,1)} -> Date | C20: Close | E20: {=_xlfn.STOCKHISTORY("XNSE:BHARTIARTL",TODAY()-730,TODAY(),1,1,0,1)} -> Date | F20: Close | H20: {=_xlfn.STOCKHISTORY("XNSE:HDFCBANK",TODAY()-730,TODAY(),1,1,0,1)} -> Date | I20: Close | K20: {=_xlfn.STOCKHISTORY("XNSE:LT",TODAY()-730,TODAY(),1,1,0,1)} -> Date | L20: Close | N20: {=_xlfn.STOCKHISTORY("XNSE:CIPLA",TODAY()-730,TODAY(),1,1,0,1)} -> Date | O20: Close | Q20: {=_xlfn.STOCKHISTORY("XNSE:MARUTI",TODAY()-730,TODAY(),1,1,0,1)} -> Date | R20: Close | T20: {=_xlfn.STOCKHISTORY("XNSE:HCLTECH",TODAY()-730,TODAY(),1,1,0,1)} -> Date | U20: Close | W20: Date | X20: Close
B21: 45544 | C21: 1472.625 | E21: 45544 | F21: 1634.45 | H21: 45544 | I21: 830.9092 | K21: 45544 | L21: 3613 | N21: 45544 | O21: 1659.7 | Q21: 45544 | R21: 12316.05 | T21: 45544 | U21: 1806.7271 | W21: 45544 | X21: 24936.4
B22: 45551 | C22: 1485.925 | E22: 45551 | F22: 1711.75 | H22: 45551 | I22: 868.4409 | K22: 45551 | L22: 3793.9 | N22: 45551 | O22: 1638.65 | Q22: 45551 | R22: 12614.5 | T22: 45551 | U22: 1754.1538 | W22: 45551 | X22: 25383.75
B23: 45558 | C23: 1526.175 | E23: 45558 | F23: 1734.6 | H23: 45558 | I23: 874.1517 | K23: 45558 | L23: 3705.65 | N23: 45558 | O23: 1672.5 | Q23: 45558 | R23: 13495.6 | T23: 45558 | U23: 1802.3419 | W23: 45558 | X23: 25939.051
B24: 45565 | C24: 1386.525 | E24: 45565 | F24: 1640.9 | H24: 45565 | I24: 826.7695 | K24: 45565 | L24: 3493.95 | N24: 45565 | O24: 1623.3 | Q24: 45565 | R24: 12605.75 | T24: 45565 | U24: 1770.6484 | W24: 45565 | X24: 25810.85
B25: 45572 | C25: 1372.1 | E25: 45572 | F25: 1687.4 | H25: 45572 | I25: 823.4528 | K25: 45572 | L25: 3482.55 | N25: 45572 | O25: 1595.75 | Q25: 45572 | R25: 12776.65 | T25: 45572 | U25: 1833.4872 | W25: 45572 | X25: 24795.75
B26: 45579 | C26: 1359.3 | E26: 45579 | F26: 1707.85 | H26: 45579 | I26: 838.8395 | K26: 45579 | L26: 3577.8 | N26: 45579 | O26: 1551.7 | Q26: 45579 | R26: 12105.1 | T26: 45579 | U26: 1851.4767 | W26: 45579 | X26: 25127.949
B27: 45586 | C27: 1327.85 | E27: 45586 | F27: 1666 | H27: 45586 | I27: 869.5382 | K27: 45586 | L27: 3326.4 | N27: 45586 | O27: 1488.9 | Q27: 45586 | R27: 11502.85 | T27: 45586 | U27: 1846.1446 | W27: 45586 | X27: 24781.1
B28: 45593 | C28: 1338.65 | E28: 45593 | F28: 1616.45 | H28: 45593 | I28: 866.4957 | K28: 45593 | L28: 3626.35 | N28: 45593 | O28: 1559.55 | Q28: 45593 | R28: 11110 | T28: 45593 | U28: 1751.5127 | W28: 45593 | X28: 24339.15
B29: 45600 | C29: 1283.75 | E29: 45600 | F29: 1569.9 | H29: 45600 | I29: 875.0495 | K29: 45600 | L29: 3660.3 | N29: 45600 | O29: 1592.6 | Q29: 45600 | R29: 11303 | T29: 45600 | U29: 1831.3444 | W29: 45600 | X29: 23995.35
B30: 45607 | C30: 1267.6 | E30: 45607 | F30: 1550.5 | H30: 45607 | I30: 844.276 | K30: 45607 | L30: 3526.25 | N30: 45607 | O30: 1499.75 | Q30: 45607 | R30: 11006.05 | T30: 45607 | U30: 1852.7225 | W30: 45607 | X30: 24141.301
B31: 45614 | C31: 1265.4 | E31: 45614 | F31: 1569.3 | H31: 45614 | I31: 870.6355 | K31: 45614 | L31: 3603.5 | N31: 45614 | O31: 1486.5 | Q31: 45614 | R31: 11063.6 | T31: 45614 | U31: 1892.0404 | W31: 45614 | X31: 23453.801
B32: 45621 | C32: 1292.2 | E32: 45621 | F32: 1627.15 | H32: 45621 | I32: 895.7979 | K32: 45621 | L32: 3724.8 | N32: 45621 | O32: 1533.9 | Q32: 45621 | R32: 11074.2 | T32: 45621 | U32: 1841.859 | W32: 45621 | X32: 24221.9
... B125: 46272 | C125: 1309.5 | E125: 46272 | F125: 1854 | H125: 46272 | I125: 710.5 | K125: 46272 | L125: 3999 | N125: 46272 | O125: 1395 | Q125: 46272 | R125: 12760 | T125: 46272 | U125: 1282.8 | W125: 46272 | X125: 23779.15

Sheet Returns
A1: RETURNS — WEEKLY SIMPLE RETURN SERIES
A2: Everything downstream in this workbook flows from these two series: column J (portfolio) and column I (NIFTY 50). | L2: MODEL CHECKS | M2: STATUS
A3: Stock / index return: = Price(t) / Price(t−1) − 1 · Portfolio return: = SUMPRODUCT(Weights, StockReturns(t)) — target weights, NOT a simple average of the seven stocks. | L3: Weights | M3: =SUM(Weights) -> 1
A4: Target weight → | B4: =Holdings!$E$7 -> 0.23 | C4: =Holdings!$E$8 -> 0.15 | D4: =Holdings!$E$9 -> 0.15 | E4: =Holdings!$E$10 -> 0.14 | F4: =Holdings!$E$11 -> 0.12 | G4: =Holdings!$E$12 -> 0.12 | H4: =Holdings!$E$13 -> 0.09 | J4: =SUM($B$4:$H$4) -> 1 | L4: Weekly observations | M4: =COUNT(PortRet) -> 104
A5: Date | B5: Reliance Industries | C5: Bharti Airtel | D5: HDFC Bank | E5: Larsen & Toubro | F5: Cipla | G5: Maruti Suzuki | H5: HCL Technologies | I5: NIFTY 50 | J5: Portfolio | L5: Missing returns | M5: =COUNTBLANK($B$6:INDEX($J$6:$J$1000,COUNT($A$6:$A$1000))) -> 0
A6: =Prices!$A$5 -> 45551 | B6: =IFERROR(Prices!B5/Prices!B4-1,"") -> 0.0090314914 | C6: =IFERROR(Prices!C5/Prices!C4-1,"") -> 0.047294197 | D6: =IFERROR(Prices!D5/Prices!D4-1,"") -> 0.045169436 | E6: =IFERROR(Prices!E5/Prices!E4-1,"") -> 0.050069195 | F6: =IFERROR(Prices!F5/Prices!F4-1,"") -> -0.012683015 | G6: =IFERROR(Prices!G5/Prices!G4-1,"") -> 0.024232607 | H6: =IFERROR(Prices!H5/Prices!H4-1,"") -> -0.029098639 | I6: =IFERROR(Prices!I5/Prices!I4-1,"") -> 0.017939622 | J6: =IFERROR(SUMPRODUCT(Weights,$B6:$H6),"") -> 0.021723549 | L6: Benchmark aligned | M6: =IF(COUNT(BenchRet)=COUNT(PortRet),"YES","CHECK") -> YES
A7: =Prices!$A$6 -> 45558 | B7: =IFERROR(Prices!B6/Prices!B5-1,"") -> 0.027087504 | C7: =IFERROR(Prices!C6/Prices!C5-1,"") -> 0.013348912 | D7: =IFERROR(Prices!D6/Prices!D5-1,"") -> 0.0065759224 | E7: =IFERROR(Prices!E6/Prices!E5-1,"") -> -0.023261024 | F7: =IFERROR(Prices!F6/Prices!F5-1,"") -> 0.020657248 | G7: =IFERROR(Prices!G6/Prices!G5-1,"") -> 0.069848191 | H7: =IFERROR(Prices!H6/Prices!H5-1,"") -> 0.027470852 | I7: =IFERROR(Prices!I6/Prices!I5-1,"") -> 0.021876231 | J7: =IFERROR(SUMPRODUCT(Weights,$B7:$H7),"") -> 0.019295337
A8: =Prices!$A$7 -> 45565 | B8: =IFERROR(Prices!B7/Prices!B6-1,"") -> -0.091503268 | C8: =IFERROR(Prices!C7/Prices!C6-1,"") -> -0.054018217 | D8: =IFERROR(Prices!D7/Prices!D6-1,"") -> -0.054203635 | E8: =IFERROR(Prices!E7/Prices!E6-1,"") -> -0.057128979 | F8: =IFERROR(Prices!F7/Prices!F6-1,"") -> -0.02941704 | G8: =IFERROR(Prices!G7/Prices!G6-1,"") -> -0.065936305 | H8: =IFERROR(Prices!H7/Prices!H6-1,"") -> -0.017584621 | I8: =IFERROR(Prices!I7/Prices!I6-1,"") -> -0.0049424003 | J8: =IFERROR(SUMPRODUCT(Weights,$B8:$H8),"") -> -0.058302104
A9: =Prices!$A$8 -> 45572 | B9: =IFERROR(Prices!B8/Prices!B7-1,"") -> -0.010403707 | C9: =IFERROR(Prices!C8/Prices!C7-1,"") -> 0.028338107 | D9: =IFERROR(Prices!D8/Prices!D7-1,"") -> -0.0040116381 | E9: =IFERROR(Prices!E8/Prices!E7-1,"") -> -0.0032627828 | F9: =IFERROR(Prices!F8/Prices!F7-1,"") -> -0.016971601 | G9: =IFERROR(Prices!G8/Prices!G7-1,"") -> 0.013557305 | H9: =IFERROR(Prices!H8/Prices!H7-1,"") -> 0.035489146 | I9: =IFERROR(Prices!I8/Prices!I7-1,"") -> -0.039328407 | J9: =IFERROR(SUMPRODUCT(Weights,$B9:$H9),"") -> 0.0035836358
A10: =Prices!$A$9 -> 45579 | B10: =IFERROR(Prices!B9/Prices!B8-1,"") -> -0.0093287661 | C10: =IFERROR(Prices!C9/Prices!C8-1,"") -> 0.012119237 | D10: =IFERROR(Prices!D9/Prices!D8-1,"") -> 0.018685588 | E10: =IFERROR(Prices!E9/Prices!E8-1,"") -> 0.027350648 | F10: =IFERROR(Prices!F9/Prices!F8-1,"") -> -0.027604575 | G10: =IFERROR(Prices!G9/Prices!G8-1,"") -> -0.052560726 | H10: =IFERROR(Prices!H9/Prices!H8-1,"") -> 0.0098116311 | I10: =IFERROR(Prices!I9/Prices!I8-1,"") -> 0.013397426 | J10: =IFERROR(SUMPRODUCT(Weights,$B10:$H10),"") -> -0.002432591
A11: =Prices!$A$10 -> 45586 | B11: =IFERROR(Prices!B10/Prices!B9-1,"") -> -0.023136909 | C11: =IFERROR(Prices!C10/Prices!C9-1,"") -> -0.024504494 | D11: =IFERROR(Prices!D10/Prices!D9-1,"") -> 0.036596631 | E11: =IFERROR(Prices!E10/Prices!E9-1,"") -> -0.070266644 | F11: =IFERROR(Prices!F10/Prices!F9-1,"") -> -0.040471741 | G11: =IFERROR(Prices!G10/Prices!G9-1,"") -> -0.049751758 | H11: =IFERROR(Prices!H10/Prices!H9-1,"") -> -0.0028799174 | I11: =IFERROR(Prices!I10/Prices!I9-1,"") -> -0.013803339 | J11: =IFERROR(SUMPRODUCT(Weights,$B11:$H11),"") -> -0.024431011
A12: =Prices!$A$11 -> 45593 | B12: =IFERROR(Prices!B11/Prices!B10-1,"") -> 0.0081334488 | C12: =IFERROR(Prices!C11/Prices!C10-1,"") -> -0.029741897 | D12: =IFERROR(Prices!D11/Prices!D10-1,"") -> -0.0034989837 | E12: =IFERROR(Prices!E11/Prices!E10-1,"") -> 0.090172559 | F12: =IFERROR(Prices!F11/Prices!F10-1,"") -> 0.047451138 | G12: =IFERROR(Prices!G11/Prices!G10-1,"") -> -0.034152406 | H12: =IFERROR(Prices!H11/Prices!H10-1,"") -> -0.051259203 | I12: =IFERROR(Prices!I11/Prices!I10-1,"") -> -0.017834125 | J12: =IFERROR(SUMPRODUCT(Weights,$B12:$H12),"") -> 0.0064912391
A13: =Prices!$A$12 -> 45600 | B13: =IFERROR(Prices!B12/Prices!B11-1,"") -> -0.041011467 | C13: =IFERROR(Prices!C12/Prices!C11-1,"") -> -0.028797674 | D13: =IFERROR(Prices!D12/Prices!D11-1,"") -> 0.0098717166 | E13: =IFERROR(Prices!E12/Prices!E11-1,"") -> 0.0093620307 | F13: =IFERROR(Prices!F12/Prices!F11-1,"") -> 0.021192011 | G13: =IFERROR(Prices!G12/Prices!G11-1,"") -> 0.017371737 | H13: =IFERROR(Prices!H12/Prices!H11-1,"") -> 0.045578716 | I13: =IFERROR(Prices!I12/Prices!I11-1,"") -> -0.014125422 | J13: =IFERROR(SUMPRODUCT(Weights,$B13:$H13),"") -> -0.0022311125
A14: =Prices!$A$13 -> 45607 | B14: =IFERROR(Prices!B13/Prices!B12-1,"") -> -0.012580331 | C14: =IFERROR(Prices!C13/Prices!C12-1,"") -> -0.012357475 | D14: =IFERROR(Prices!D13/Prices!D12-1,"") -> -0.035167725 | E14: =IFERROR(Prices!E13/Prices!E12-1,"") -> -0.036622681 | F14: =IFERROR(Prices!F13/Prices!F12-1,"") -> -0.058300892 | G14: =IFERROR(Prices!G13/Prices!G12-1,"") -> -0.026271786 | H14: =IFERROR(Prices!H13/Prices!H12-1,"") -> 0.011673446 | I14: =IFERROR(Prices!I13/Prices!I12-1,"") -> 0.0060824774 | J14: =IFERROR(SUMPRODUCT(Weights,$B14:$H14),"") -> -0.024247543
A15: =Prices!$A$14 -> 45614 | B15: =IFERROR(Prices!B14/Prices!B13-1,"") -> -0.0017355633 | C15: =IFERROR(Prices!C14/Prices!C13-1,"") -> 0.012125121 | D15: =IFERROR(Prices!D14/Prices!D13-1,"") -> 0.031221425 | E15: =IFERROR(Prices!E14/Prices!E13-1,"") -> 0.021907125 | F15: =IFERROR(Prices!F14/Prices!F13-1,"") -> -0.0088348058 | G15: =IFERROR(Prices!G14/Prices!G13-1,"") -> 0.0052289423 | H15: =IFERROR(Prices!H14/Prices!H13-1,"") -> 0.021221689 | I15: =IFERROR(Prices!I14/Prices!I13-1,"") -> -0.028478167 | J15: =IFERROR(SUMPRODUCT(Weights,$B15:$H15),"") -> 0.010647048
A16: =Prices!$A$15 -> 45621 | B16: =IFERROR(Prices!B15/Prices!B14-1,"") -> 0.021179074 | C16: =IFERROR(Prices!C15/Prices!C14-1,"") -> 0.03686357 | D16: =IFERROR(Prices!D15/Prices!D14-1,"") -> 0.028901188 | E16: =IFERROR(Prices!E15/Prices!E14-1,"") -> 0.033661718 | F16: =IFERROR(Prices!F15/Prices!F14-1,"") -> 0.031886983 | G16: =IFERROR(Prices!G15/Prices!G14-1,"") -> 0.00095809682 | H16: =IFERROR(Prices!H15/Prices!H14-1,"") -> -0.026522372 | I16: =IFERROR(Prices!I15/Prices!I14-1,"") -> 0.032749473 | J16: =IFERROR(SUMPRODUCT(Weights,$B16:$H16),"") -> 0.021002937
A17: =Prices!$A$16 -> 45628 | B17: =IFERROR(Prices!B16/Prices!B15-1,"") -> 0.014974462 | C17: =IFERROR(Prices!C16/Prices!C15-1,"") -> -0.018006945 | D17: =IFERROR(Prices!D16/Prices!D15-1,"") -> 0.033295233 | E17: =IFERROR(Prices!E16/Prices!E15-1,"") -> 0.038096005 | F17: =IFERROR(Prices!F16/Prices!F15-1,"") -> -0.036834213 | G17: =IFERROR(Prices!G16/Prices!G15-1,"") -> 0.022010619 | H17: =IFERROR(Prices!H16/Prices!H15-1,"") -> 0.040393972 | I17: =IFERROR(Prices!I16/Prices!I15-1,"") -> 0.0022355963 | J17: =IFERROR(SUMPRODUCT(Weights,$B17:$H17),"") -> 0.012927436
A18: =Prices!$A$17 -> 45635 | B18: =IFERROR(Prices!B17/Prices!B16-1,"") -> -0.029507072 | C18: =IFERROR(Prices!C17/Prices!C16-1,"") -> 0.052508058 | D18: =IFERROR(Prices!D17/Prices!D16-1,"") -> 0.0085675205 | E18: =IFERROR(Prices!E17/Prices!E16-1,"") -> 0.0052499547 | F18: =IFERROR(Prices!F17/Prices!F16-1,"") -> -0.020373629 | G18: =IFERROR(Prices!G17/Prices!G16-1,"") -> -0.0040113271 | H18: =IFERROR(Prices!H17/Prices!H16-1,"") -> 0.023976665 | I18: =IFERROR(Prices!I17/Prices!I16-1,"") -> 0.01412706 | J18: =IFERROR(SUMPRODUCT(Weights,$B18:$H18),"") -> 0.0023414089
A19: =Prices!$A$18 -> 45642 | B19: =IFERROR(Prices!B18/Prices!B17-1,"") -> -0.053069883 | C19: =IFERROR(Prices!C18/Prices!C17-1,"") -> -0.061632228 | D19: =IFERROR(Prices!D18/Prices!D17-1,"") -> -0.053559516 | E19: =IFERROR(Prices!E18/Prices!E17-1,"") -> -0.066156419 | F19: =IFERROR(Prices!F18/Prices!F17-1,"") -> 0.017100808 | G19: =IFERROR(Prices!G18/Prices!G17-1,"") -> -0.032956163 | H19: =IFERROR(Prices!H18/Prices!H17-1,"") -> -0.02918019 | I19: =IFERROR(Prices!I18/Prices!I17-1,"") -> 0.0020004874 | J19: =IFERROR(SUMPRODUCT(Weights,$B19:$H19),"") -> -0.043275593
A20: =Prices!$A$19 -> 45649 | B20: =IFERROR(Prices!B19/Prices!B18-1,"") -> 0.013067286 | C20: =IFERROR(Prices!C19/Prices!C18-1,"") -> 0.013782397 | D20: =IFERROR(Prices!D19/Prices!D18-1,"") -> 0.015100277 | E20: =IFERROR(Prices!E19/Prices!E18-1,"") -> -0.0059919831 | F20: =IFERROR(Prices!F19/Prices!F18-1,"") -> 0.02347067 | G20: =IFERROR(Prices!G19/Prices!G18-1,"") -> 0.0036693713 | H20: =IFERROR(Prices!H19/Prices!H18-1,"") -> -0.010123746 | I20: =IFERROR(Prices!I19/Prices!I18-1,"") -> -0.037084138 | J20: =IFERROR(SUMPRODUCT(Weights,$B20:$H20),"") -> 0.0088446671
A21: =Prices!$A$20 -> 45656 | B21: =IFERROR(Prices!B20/Prices!B19-1,"") -> 0.024650915 | C21: =IFERROR(Prices!C20/Prices!C19-1,"") -> -0.0006250586 | D21: =IFERROR(Prices!D20/Prices!D19-1,"") -> -0.027276542 | E21: =IFERROR(Prices!E20/Prices!E19-1,"") -> 0.014356587 | F21: =IFERROR(Prices!F20/Prices!F19-1,"") -> 0.0030864198 | G21: =IFERROR(Prices!G20/Prices!G19-1,"") -> 0.090777393 | H21: =IFERROR(Prices!H20/Prices!H19-1,"") -> 0.028884766 | I21: =IFERROR(Prices!I20/Prices!I19-1,"") -> -0.0045698133 | J21: =IFERROR(SUMPRODUCT(Weights,$B21:$H21),"") -> 0.017357679
A22: =Prices!$A$21 -> 45663 | B22: =IFERROR(Prices!B21/Prices!B20-1,"") -> -0.0073931983 | C22: =IFERROR(Prices!C21/Prices!C20-1,"") -> 0.010663915 | D22: =IFERROR(Prices!D21/Prices!D20-1,"") -> -0.052852776 | E22: =IFERROR(Prices!E21/Prices!E20-1,"") -> -0.033812399 | F22: =IFERROR(Prices!F21/Prices!F20-1,"") -> -0.02808933 | G22: =IFERROR(Prices!G21/Prices!G20-1,"") -> -0.02540168 | H22: =IFERROR(Prices!H21/Prices!H20-1,"") -> 0.024888916 | I22: =IFERROR(Prices!I21/Prices!I20-1,"") -> -0.0012201197 | J22: =IFERROR(SUMPRODUCT(Weights,$B22:$H22),"") -> -0.016941419
A23: =Prices!$A$22 -> 45670 | B23: =IFERROR(Prices!B22/Prices!B21-1,"") -> 0.048675417 | C23: =IFERROR(Prices!C22/Prices!C21-1,"") -> 0.007178662 | D23: =IFERROR(Prices!D22/Prices!D21-1,"") -> -0.012071828 | E23: =IFERROR(Prices!E22/Prices!E21-1,"") -> 0.0091907866 | F23: =IFERROR(Prices!F22/Prices!F21-1,"") -> -0.018041939 | G23: =IFERROR(Prices!G22/Prices!G21-1,"") -> 0.043439571 | H23: =IFERROR(Prices!H22/Prices!H21-1,"") -> -0.10033935 | I23: =IFERROR(Prices!I22/Prices!I21-1,"") -> -0.022446664 | J23: =IFERROR(SUMPRODUCT(Weights,$B23:$H23),"") -> 0.0057652559
A24: =Prices!$A$23 -> 45677 | B24: =IFERROR(Prices!B23/Prices!B22-1,"") -> -0.043037586 | C24: =IFERROR(Prices!C23/Prices!C22-1,"") -> 0.0106298 | D24: =IFERROR(Prices!D23/Prices!D22-1,"") -> 0.0079730957 | E24: =IFERROR(Prices!E23/Prices!E22-1,"") -> -0.030950079 | F24: =IFERROR(Prices!F23/Prices!F22-1,"") -> -0.021424114 | G24: =IFERROR(Prices!G23/Prices!G22-1,"") -> -0.013879791 | H24: =IFERROR(Prices!H23/Prices!H22-1,"") -> 0.0022080608 | I24: =IFERROR(Prices!I23/Prices!I22-1,"") -> 0.011210316 | J24: =IFERROR(SUMPRODUCT(Weights,$B24:$H24),"") -> -0.015478965
A25: =Prices!$A$24 -> 45684 | B25: =IFERROR(Prices!B24/Prices!B23-1,"") -> 0.014683463 | C25: =IFERROR(Prices!C24/Prices!C23-1,"") -> -0.013101897 | D25: =IFERROR(Prices!D24/Prices!D23-1,"") -> 0.02494245 | E25: =IFERROR(Prices!E24/Prices!E23-1,"") -> -0.0030940952 | F25: =IFERROR(Prices!F24/Prices!F23-1,"") -> 0.01990931 | G25: =IFERROR(Prices!G24/Prices!G23-1,"") -> 0.079262026 | H25: =IFERROR(Prices!H24/Prices!H23-1,"") -> -0.055135678 | I25: =IFERROR(Prices!I24/Prices!I23-1,"") -> -0.02208632 | J25: =IFERROR(SUMPRODUCT(Weights,$B25:$H25),"") -> 0.011658455
A26: =Prices!$A$25 -> 45691 | B26: =IFERROR(Prices!B25/Prices!B24-1,"") -> 0.0016606041 | C26: =IFERROR(Prices!C25/Prices!C24-1,"") -> 0.032958571 | D26: =IFERROR(Prices!D25/Prices!D24-1,"") -> 0.024719871 | E26: =IFERROR(Prices!E25/Prices!E24-1,"") -> -0.032081218 | F26: =IFERROR(Prices!F25/Prices!F24-1,"") -> 0.022750955 | G26: =IFERROR(Prices!G25/Prices!G24-1,"") -> 0.010296907 | H26: =IFERROR(Prices!H25/Prices!H24-1,"") -> 0.018683589 | I26: =IFERROR(Prices!I25/Prices!I24-1,"") -> 0.023299176 | J26: =IFERROR(SUMPRODUCT(Weights,$B26:$H26),"") -> 0.010189601
A27: =Prices!$A$26 -> 45698 | B27: =IFERROR(Prices!B26/Prices!B25-1,"") -> -0.039038446 | C27: =IFERROR(Prices!C26/Prices!C25-1,"") -> 0.024034591 | D27: =IFERROR(Prices!D26/Prices!D25-1,"") -> -0.021872741 | E27: =IFERROR(Prices!E26/Prices!E25-1,"") -> -0.029743175 | F27: =IFERROR(Prices!F26/Prices!F25-1,"") -> -0.0086941756 | G27: =IFERROR(Prices!G26/Prices!G25-1,"") -> -0.028296103 | H27: =IFERROR(Prices!H26/Prices!H25-1,"") -> -0.0083446817 | I27: =IFERROR(Prices!I26/Prices!I25-1,"") -> 0.00087961917 | J27: =IFERROR(SUMPRODUCT(Weights,$B27:$H27),"") -> -0.018008464
A28: =Prices!$A$27 -> 45705 | B28: =IFERROR(Prices!B27/Prices!B26-1,"") -> 0.0089546108 | C28: =IFERROR(Prices!C27/Prices!C26-1,"") -> -0.045310271 | D28: =IFERROR(Prices!D27/Prices!D26-1,"") -> -0.0013865699 | E28: =IFERROR(Prices!E27/Prices!E26-1,"") -> 0.023921672 | F28: =IFERROR(Prices!F27/Prices!F26-1,"") -> 0.011168591 | G28: =IFERROR(Prices!G27/Prices!G26-1,"") -> -0.028138246 | H28: =IFERROR(Prices!H27/Prices!H26-1,"") -> -0.006165084 | I28: =IFERROR(Prices!I27/Prices!I26-1,"") -> -0.01805264 | J28: =IFERROR(SUMPRODUCT(Weights,$B28:$H28),"") -> -0.0041871478
A29: =Prices!$A$28 -> 45712 | B29: =IFERROR(Prices!B28/Prices!B27-1,"") -> -0.02283923 | C29: =IFERROR(Prices!C28/Prices!C27-1,"") -> -0.042122922 | D29: =IFERROR(Prices!D28/Prices!D27-1,"") -> 0.023574565 | E29: =IFERROR(Prices!E28/Prices!E27-1,"") -> -0.045624566 | F29: =IFERROR(Prices!F28/Prices!F27-1,"") -> -0.046247671 | G29: =IFERROR(Prices!G28/Prices!G27-1,"") -> -0.03064077 | H29: =IFERROR(Prices!H28/Prices!H27-1,"") -> -0.073881343 | I29: =IFERROR(Prices!I28/Prices!I27-1,"") -> -0.017689862 | J29: =IFERROR(SUMPRODUCT(Weights,$B29:$H29),"") -> -0.030298649
